<robot name="GEN3-7DOF-VISION_ARM_URDF_V12" version="1.0">
  <link name="Base_Link_0">
    <inertial>
      <origin xyz="0   0   0.04" rpy="0 0 0" />
      <mass value="1.697" />
      <inertia ixx="0.003" ixy="0" ixz="0" iyy="0.003" iyz="0" izz="0.005" />
    </inertial>
    <visual>
      <origin xyz="0 0 0" rpy="0 0 0" />
      <geometry>
        <mesh filename="package://kortex_description/arms/gen3/7dof/meshes/base_link.STL" />
      </geometry>
      <material name="">
        <color rgba="0.75294 0.75294 0.75294 1" />
      </material>
    </visual>
    <collision>
      <origin xyz="0 0 0" rpy="0 0 0" />
      <geometry>
        <mesh filename="package://kortex_description/arms/gen3/7dof/meshes/base_link.STL" />
      </geometry>
    </collision>
  </link>


  <link name="Link_1">
    <inertial>
      <origin xyz="0   0   0.025" rpy="0 0 0" />
      <mass value="1.3773" />
      <inertia ixx="0.00034" ixy="1E-06" ixz="2E-06" iyy="0.00034" iyz="0.000448" izz="0.00027" />
    </inertial>
    <visual>
      <origin xyz="0 0 0" rpy="0 0 0" />
      <geometry>
        <mesh filename="package://kortex_description/arms/gen3/7dof/meshes/shoulder_link.STL" />
      </geometry>
      <material name="">
        <color rgba="0.75294 0.75294 0.75294 1" />
      </material>
    </visual>
    <collision>
      <origin xyz="0 0 0" rpy="0 0 0" />
      <geometry>
        <mesh filename="package://kortex_description/arms/gen3/7dof/meshes/shoulder_link.STL" />
      </geometry>
    </collision>
  </link>


  <joint name="joint_1" type="continuous">
    <origin xyz="0   0   0.08" rpy="0   0   0" />
    <parent link="Base_Link_0" />
    <child link="Link_1" />
    <axis xyz="0 0 1" />
    <limit effort="39" velocity="1.3963" />
  </joint>


  <link name="Link_2">
    <inertial>
      <origin xyz="0   0.08   0" rpy="0 0 0" />
      <mass value="1.1636" />
      <inertia ixx="0.00227" ixy="0" ixz="0" iyy="0.00027"  iyz="0" izz="0.00227" />
    </inertial>
    <visual>
      <origin xyz="0 0 0" rpy="0 0 0" />
      <geometry>
        <mesh filename="package://kortex_description/arms/gen3/7dof/meshes/half_arm_1_link.STL" />
      </geometry>
      <material name="">
        <color rgba="0.75294 0.75294 0.75294 1" />
      </material>
    </visual>
    <collision>
      <origin xyz="0 0 0" rpy="0 0 0" />
      <geometry>
        <mesh filename="package://kortex_description/arms/gen3/7dof/meshes/half_arm_1_link.STL" />
      </geometry>
    </collision>
  </link>


  <joint name="joint_2" type="revolute">
    <origin xyz="0   0   0.05" rpy="1.5708   0   0" />
    <parent link="Link_1" />
    <child link="Link_2" />
    <axis xyz="0 0 1" />
    <limit lower="-2.24" upper="2.24" effort="39" velocity="1.3963" />
  </joint>


  <link name="Link_3">
    <inertial>
      <origin xyz="0   0.025   0" rpy="0 0 0" />
      <mass value="1.1636" />
      <inertia ixx="0.00034" ixy="0" ixz="0" iyy="0.00027" iyz="0" izz="0.00034" />
    </inertial>
    <visual>
      <origin xyz="0 0 0" rpy="0 0 0" />
      <geometry>
        <mesh filename="package://kortex_description/arms/gen3/7dof/meshes/half_arm_2_link.STL" />
      </geometry>
      <material name="">
        <color rgba="0.75294 0.75294 0.75294 1" />
      </material>
    </visual>
    <collision>
      <origin xyz="0 0 0" rpy="0 0 0" />
      <geometry>
        <mesh filename="package://kortex_description/arms/gen3/7dof/meshes/half_arm_2_link.STL" />
      </geometry>
    </collision>
  </link>


  <joint name="joint_3" type="continuous">
    <origin xyz="0   0.16   0" rpy="0   0   0" />
    <parent link="Link_2" />
    <child link="Link_3" />
    <axis xyz="0 0 1" />
    <limit effort="39" velocity="1.3963" />
  </joint>


  <link name="Link_4">
    <inertial>
      <origin xyz="0   0   0.05" rpy="0   0   0" />
      <mass value="0.9302" />
      <inertia ixx="0.00097" ixy="0" ixz="0" iyy="0.00097" iyz="0" izz="0.00027" />
    </inertial>
    <visual>
      <origin xyz="0 0 0" rpy="0 0 0" />
      <geometry>
        <mesh filename="package://kortex_description/arms/gen3/7dof/meshes/forearm_link.STL" />
      </geometry>
      <material name="">
        <color rgba="0.75294 0.75294 0.75294 1" />
      </material>
    </visual>
    <collision>
      <origin xyz="0 0 0" rpy="0 0 0" />
      <geometry>
        <mesh filename="package://kortex_description/arms/gen3/7dof/meshes/forearm_link.STL" />
      </geometry>
    </collision>
  </link>


  <joint name="joint_4" type="revolute">
    <origin xyz="0   0.05   0" rpy="-1.5708   0   0" />
    <parent link="Link_3" />
    <child link="Link_4" />
    <axis xyz="0 0 1" />
    <limit lower="-2.57" upper="2.57" effort="39" velocity="1.3963" />
  </joint>


  <link name="end_effector_link">
    <inertial>
      <origin xyz="0 0 0" rpy="0 0 0" />
      <mass value="0" />
      <inertia ixx="0" ixy="0" ixz="0" iyy="0" iyz="0" izz="0" />
    </inertial>
  </link>


  <joint name="end_effector" type="fixed">
    <origin xyz="0   0   0.1" rpy="0   0   0" />
    <parent link="Link_4" />
    <child link="end_effector_link" />
    <axis xyz="0 0 0" />
  </joint>
</robot>
